Workbook

Sheet Métricas
A1: jh
B2: 📊 DASHBOARD CRM — OPENCORE
B4: Total Prospectos | C4: Contactadas | D4: No Contactadas | E4: Reuniones Agendadas | F4: Tasa de Conversión
B5: =COUNTA(CUENTAS_VIP_TOP!A:A)-1+COUNTA(INTELIGENCIA_MERCADO!A:A)-1+COUNTA(BASE_COMPLETA_LIMPIA!A:A)-1 | C5: =COUNTIF(CUENTAS_VIP_TOP!N:N, "Contactada")+COUNTIF(INTELIGENCIA_MERCADO!M:M, "Contactada")+COUNTIF(BASE_COMPLETA_LIMPIA!L:L, "Contactada") | D5: =B5-C5 | E5: =COUNTIF(CUENTAS_VIP_TOP!O:O, "Reunión agendada")+COUNTIF(INTELIGENCIA_MERCADO!N:N, "Reunión agendada")+COUNTIF(BASE_COMPLETA_LIMPIA!M:M, "Reunión agendada") | F5: =IF(C5=0, 0, E5/C5)
B7: Resumen por Segmento | C7: VIP Top | D7: Intelig. Mercado | E7: Base Completa | F7: TOTAL
B8: Total Prospectos | C8: =COUNTA(CUENTAS_VIP_TOP!A:A)-1 | D8: =COUNTA(INTELIGENCIA_MERCADO!A:A)-1 | E8: =COUNTA(BASE_COMPLETA_LIMPIA!A:A)-1 | F8: =COUNTA(CUENTAS_VIP_TOP!A:A)-1+COUNTA(INTELIGENCIA_MERCADO!A:A)-1+COUNTA(BASE_COMPLETA_LIMPIA!A:A)-1
B9: Contactadas | C9: =COUNTIF(CUENTAS_VIP_TOP!N:N, "Contactada") | D9: =COUNTIF(INTELIGENCIA_MERCADO!M:M, "Contactada") | E9: =COUNTIF(BASE_COMPLETA_LIMPIA!L:L, "Contactada") | F9: =COUNTIF(CUENTAS_VIP_TOP!N:N, "Contactada")+COUNTIF(INTELIGENCIA_MERCADO!M:M, "Contactada")+COUNTIF(BASE_COMPLETA_LIMPIA!L:L, "Contactada")
B10: No Contactadas | C10: =C8-C9 | D10: =D8-D9 | E10: =E8-E9 | F10: =F8-F9
B12: Estado de Gestión | C12: VIP Top | D12: Intelig. Mercado | E12: Base Completa | F12: TOTAL
B13: Reunión agendada | C13: =COUNTIF(CUENTAS_VIP_TOP!O:O, "Reunión agendada") | D13: =COUNTIF(INTELIGENCIA_MERCADO!N:N, "Reunión agendada") | E13: =COUNTIF(BASE_COMPLETA_LIMPIA!M:M, "Reunión agendada") | F13: =COUNTIF(CUENTAS_VIP_TOP!O:O, "Reunión agendada")+COUNTIF(INTELIGENCIA_MERCADO!N:N, "Reunión agendada")+COUNTIF(BASE_COMPLETA_LIMPIA!M:M, "Reunión agendada")
B14: No Reunión | C14: =COUNTIF(CUENTAS_VIP_TOP!O:O, "No Reunión") | D14: =COUNTIF(INTELIGENCIA_MERCADO!N:N, "No Reunión") | E14: =COUNTIF(BASE_COMPLETA_LIMPIA!M:M, "No Reunión") | F14: =COUNTIF(CUENTAS_VIP_TOP!O:O, "No Reunión")+COUNTIF(INTELIGENCIA_MERCADO!N:N, "No Reunión")+COUNTIF(BASE_COMPLETA_LIMPIA!M:M, "No Reunión")
B15: No le interesó | C15: =COUNTIF(CUENTAS_VIP_TOP!O:O, "No le interesó") | D15: =COUNTIF(INTELIGENCIA_MERCADO!N:N, "No le interesó") | E15: =COUNTIF(BASE_COMPLETA_LIMPIA!M:M, "No le interesó") | F15: =COUNTIF(CUENTAS_VIP_TOP!O:O, "No le interesó")+COUNTIF(INTELIGENCIA_MERCADO!N:N, "No le interesó")+COUNTIF(BASE_COMPLETA_LIMPIA!M:M, "No le interesó")
B16: Lo verá | C16: =COUNTIF(CUENTAS_VIP_TOP!O:O, "Lo verá") | D16: =COUNTIF(INTELIGENCIA_MERCADO!N:N, "Lo verá") | E16: =COUNTIF(BASE_COMPLETA_LIMPIA!M:M, "Lo verá") | F16: =COUNTIF(CUENTAS_VIP_TOP!O:O, "Lo verá")+COUNTIF(INTELIGENCIA_MERCADO!N:N, "Lo verá")+COUNTIF(BASE_COMPLETA_LIMPIA!M:M, "Lo verá")
B17: Me llamará | C17: =COUNTIF(CUENTAS_VIP_TOP!O:O, "Me llamará") | D17: =COUNTIF(INTELIGENCIA_MERCADO!N:N, "Me llamará") | E17: =COUNTIF(BASE_COMPLETA_LIMPIA!M:M, "Me llamará") | F17: =COUNTIF(CUENTAS_VIP_TOP!O:O, "Me llamará")+COUNTIF(INTELIGENCIA_MERCADO!N:N, "Me llamará")+COUNTIF(BASE_COMPLETA_LIMPIA!M:M, "Me llamará")
B18: Otro | C18: =COUNTIF(CUENTAS_VIP_TOP!O:O, "Otro") | D18: =COUNTIF(INTELIGENCIA_MERCADO!N:N, "Otro") | E18: =COUNTIF(BASE_COMPLETA_LIMPIA!M:M, "Otro") | F18: =COUNTIF(CUENTAS_VIP_TOP!O:O, "Otro")+COUNTIF(INTELIGENCIA_MERCADO!N:N, "Otro")+COUNTIF(BASE_COMPLETA_LIMPIA!M:M, "Otro")
B21: Canal de Contacto | C21: VIP Top | D21: Intelig. Mercado | E21: Base Completa | F21: TOTAL
B22: LinkedIn | C22: =COUNTIF(CUENTAS_VIP_TOP!R:R, "LinkedIn") | D22: =COUNTIF(INTELIGENCIA_MERCADO!Q:Q, "LinkedIn") | E22: =COUNTIF(BASE_COMPLETA_LIMPIA!P:P, "LinkedIn") | F22: =COUNTIF(CUENTAS_VIP_TOP!R:R, "LinkedIn")+COUNTIF(INTELIGENCIA_MERCADO!Q:Q, "LinkedIn")+COUNTIF(BASE_COMPLETA_LIMPIA!P:P, "LinkedIn")
B23: Correo | C23: =COUNTIF(CUENTAS_VIP_TOP!R:R, "Correo") | D23: =COUNTIF(INTELIGENCIA_MERCADO!Q:Q, "Correo") | E23: =COUNTIF(BASE_COMPLETA_LIMPIA!P:P, "Correo") | F23: =COUNTIF(CUENTAS_VIP_TOP!R:R, "Correo")+COUNTIF(INTELIGENCIA_MERCADO!Q:Q, "Correo")+COUNTIF(BASE_COMPLETA_LIMPIA!P:P, "Correo")
B24: Teléfono | C24: =COUNTIF(CUENTAS_VIP_TOP!R:R, "Teléfono") | D24: =COUNTIF(INTELIGENCIA_MERCADO!Q:Q, "Teléfono") | E24: =COUNTIF(BASE_COMPLETA_LIMPIA!P:P, "Teléfono") | F24: =COUNTIF(CUENTAS_VIP_TOP!R:R, "Teléfono")+COUNTIF(INTELIGENCIA_MERCADO!Q:Q, "Teléfono")+COUNTIF(BASE_COMPLETA_LIMPIA!P:P, "Teléfono")
B25: Contacto Directo | C25: =COUNTIF(CUENTAS_VIP_TOP!R:R, "Contacto Directo") | D25: =COUNTIF(INTELIGENCIA_MERCADO!Q:Q, "Contacto Directo") | E25: =COUNTIF(BASE_COMPLETA_LIMPIA!P:P, "Contacto Directo") | F25: =COUNTIF(CUENTAS_VIP_TOP!R:R, "Contacto Directo")+COUNTIF(INTELIGENCIA_MERCADO!Q:Q, "Contacto Directo")+COUNTIF(BASE_COMPLETA_LIMPIA!P:P, "Contacto Directo")
B28: Conversión por Canal | C28: Contactados | D28: Reuniones | E28: Tasa de Éxito
B29: LinkedIn | C29: =COUNTIF(CUENTAS_VIP_TOP!R:R, "LinkedIn")+COUNTIF(INTELIGENCIA_MERCADO!Q:Q, "LinkedIn")+COUNTIF(BASE_COMPLETA_LIMPIA!P:P, "LinkedIn") | D29: =COUNTIFS(CUENTAS_VIP_TOP!R:R, "LinkedIn", CUENTAS_VIP_TOP!O:O, "Reunión agendada")+COUNTIFS(INTELIGENCIA_MERCADO!Q:Q, "LinkedIn", INTELIGENCIA_MERCADO!N:N, "Reunión agendada")+COUNTIFS(BASE_COMPLETA_LIMPIA!P:P, "LinkedIn", BASE_COMPLETA_LIMPIA!M:M, "Reunión agendada") | E29: =IF(C29=0, 0, D29/C29)
B30: Correo | C30: =COUNTIF(CUENTAS_VIP_TOP!R:R, "Correo")+COUNTIF(INTELIGENCIA_MERCADO!Q:Q, "Correo")+COUNTIF(BASE_COMPLETA_LIMPIA!P:P, "Correo") | D30: =COUNTIFS(CUENTAS_VIP_TOP!R:R, "Correo", CUENTAS_VIP_TOP!O:O, "Reunión agendada")+COUNTIFS(INTELIGENCIA_MERCADO!Q:Q, "Correo", INTELIGENCIA_MERCADO!N:N, "Reunión agendada")+COUNTIFS(BASE_COMPLETA_LIMPIA!P:P, "Correo", BASE_COMPLETA_LIMPIA!M:M, "Reunión agendada") | E30: =IF(C30=0, 0, D30/C30)
B31: Teléfono | C31: =COUNTIF(CUENTAS_VIP_TOP!R:R, "Teléfono")+COUNTIF(INTELIGENCIA_MERCADO!Q:Q, "Teléfono")+COUNTIF(BASE_COMPLETA_LIMPIA!P:P, "Teléfono") | D31: =COUNTIFS(CUENTAS_VIP_TOP!R:R, "Teléfono", CUENTAS_VIP_TOP!O:O, "Reunión agendada")+COUNTIFS(INTELIGENCIA_MERCADO!Q:Q, "Teléfono", INTELIGENCIA_MERCADO!N:N, "Reunión agendada")+COUNTIFS(BASE_COMPLETA_LIMPIA!P:P, "Teléfono", BASE_COMPLETA_LIMPIA!M:M, "Reunión agendada") | E31: =IF(C31=0, 0, D31/C31)
B32: Contacto Directo | C32: =COUNTIF(CUENTAS_VIP_TOP!R:R, "Contacto Directo")+COUNTIF(INTELIGENCIA_MERCADO!Q:Q, "Contacto Directo")+COUNTIF(BASE_COMPLETA_LIMPIA!P:P, "Contacto Directo") | D32: =COUNTIFS(CUENTAS_VIP_TOP!R:R, "Contacto Directo", CUENTAS_VIP_TOP!O:O, "Reunión agendada")+COUNTIFS(INTELIGENCIA_MERCADO!Q:Q, "Contacto Directo", INTELIGENCIA_MERCADO!N:N, "Reunión agendada")+COUNTIFS(BASE_COMPLETA_LIMPIA!P:P, "Contacto Directo", BASE_COMPLETA_LIMPIA!M:M, "Reunión agendada") | E32: =IF(C32=0, 0, D32/C32)
B35: Pipeline (Embudo) | C35: Cantidad | D35: % del Total
B36: Total Prospectos | C36: =COUNTA(CUENTAS_VIP_TOP!A:A)-1+COUNTA(INTELIGENCIA_MERCADO!A:A)-1+COUNTA(BASE_COMPLETA_LIMPIA!A:A)-1 | D36: =IF(C$36=0, 0, C36/C$36)
B37: Contactadas | C37: =COUNTIF(CUENTAS_VIP_TOP!N:N, "Contactada")+COUNTIF(INTELIGENCIA_MERCADO!M:M, "Contactada")+COUNTIF(BASE_COMPLETA_LIMPIA!L:L, "Contactada") | D37: =IF(C$36=0, 0, C37/C$36)
B38: En Seguimiento | C38: =COUNTIF(CUENTAS_VIP_TOP!O:O, "Lo verá")+COUNTIF(INTELIGENCIA_MERCADO!N:N, "Lo verá")+COUNTIF(BASE_COMPLETA_LIMPIA!M:M, "Lo verá")+COUNTIF(CUENTAS_VIP_TOP!O:O, "Me llamará")+COUNTIF(INTELIGENCIA_MERCADO!N:N, "Me llamará")+COUNTIF(BASE_COMPLETA_LIMPIA!M:M, "Me llamará") | D38: =IF(C$36=0, 0, C38/C$36)
B39: Reuniones Agendadas | C39: =COUNTIF(CUENTAS_VIP_TOP!O:O, "Reunión agendada")+COUNTIF(INTELIGENCIA_MERCADO!N:N, "Reunión agendada")+COUNTIF(BASE_COMPLETA_LIMPIA!M:M, "Reunión agendada") | D39: =IF(C$36=0, 0, C39/C$36)
B42: Seguimientos | C42: Cantidad
B43: ⚠ Vencidos (pasó la fecha) | C43: =COUNTIFS(CUENTAS_VIP_TOP!S:S, "<"&TODAY(), CUENTAS_VIP_TOP!S:S, "<>"&"")+COUNTIFS(INTELIGENCIA_MERCADO!R:R, "<"&TODAY(), INTELIGENCIA_MERCADO!R:R, "<>"&"")+COUNTIFS(BASE_COMPLETA_LIMPIA!Q:Q, "<"&TODAY(), BASE_COMPLETA_LIMPIA!Q:Q, "<>"&"")
B44: 📌 Para Hoy | C44: =COUNTIFS(CUENTAS_VIP_TOP!S:S, "="&TODAY())+COUNTIFS(INTELIGENCIA_MERCADO!R:R, "="&TODAY())+COUNTIFS(BASE_COMPLETA_LIMPIA!Q:Q, "="&TODAY())
B45: 📅 Pendientes (futuro) | C45: =COUNTIFS(CUENTAS_VIP_TOP!S:S, ">"&TODAY())+COUNTIFS(INTELIGENCIA_MERCADO!R:R, ">"&TODAY())+COUNTIFS(BASE_COMPLETA_LIMPIA!Q:Q, ">"&TODAY())

Sheet INTELIGENCIA_MERCADO
A1: Empresa | B1: Rubro | C1: Ciudad | D1: Proyecto / Oportunidad Detectada | E1: Fuente de Información | F1: Enlace a la Fuente | G1: Contacto Sniper | H1: Email de Contacto | I1: LinkedIn | J1: LinkedIn Empresa | K1: Sitio Web | L1: Contexto Empresa | M1: Estado Contacto | N1: Sub-Estado | O1: Fecha Contacto | P1: Notas CRM | Q1: Medio de Contacto | R1: Próximo Seguimiento | S1: Prioridad | T1: RUT | U1: Teléfono | V1: Fecha_Email_Enviado
A2: A. Hartrodt Chile S.A. | B2: Transporte Aéreo, Transporte Marítimo, Transporte Terrestre | C2: Santiago | D2: Investigación en Proceso | G2: Hector Calderon (Jefe Informática) | H2: hcalderon@hartrodt.cl | I2: https://cl.linkedin.com/in/hector-calderon-gonzalez-3439a358 | J2: https://cl.linkedin.com/company/a-hartrodt-chile | L2: Ventas: GRANDE 3 (600.000 - 1.000.000 UF) | Empleados: 34 | M2: Contactada | Q2: LinkedIn | T2: 84.007.300-9 | U2: (56) 2 2483 7000
A3: A.J. Broom y Cía. S.A.C. | B3: Agencias Marítimas | C3: Santiago | D3: Plataforma Tracking Marítimo Real-Time | F3: https://www.ajbroom.cl/ | G3: Ricardo Lira (Gerente Operaciones) | J3: https://cl.linkedin.com/company/broom-group | L3: Ventas: GRANDE 2 (200.000 - 600.000 UF) | Empleados: 33 | M3: Contactada | Q3: LinkedIn | T3: 91.256.000-7 | U3: (56) 2 2549 8400
A4: AB Arriendos S.A. | B4: Arriendo de Equipos para Soldar, Compresores | C4: Santiago | D4: Expansión Arriendo Maquinaria Norte | F4: https://www.abarriendos.cl/ | G4: Roberto Carlos Bailac (Exec. Director) | J4: https://cl.linkedin.com/company/abarriendos | L4: Ventas: GRANDE 2 (200.000 - 600.000 UF) | Empleados: 107 | M4: Contactada | Q4: LinkedIn | T4: 96.872.010-4 | U4: (56) 2 2351 5400
A5: Aceros Chilca | B5: Bolas de Acero Forjado para Molienda, Bolas para molienda, Revestimientos para Molinos | C5: Santiago | D5: Modernización Fundición Piezas Mineras | F5: https://www.aceroschilca.com/ | G5: Eduardo Garcia (Country Manager) | J5: https://cl.linkedin.com/company/aceros-chilca-mepsa | L5: Ventas: GRANDE 2 (200.000 - 600.000 UF) | Empleados: 4 | M5: No Contactada | T5: 96.871.960-2 | U5: (56) 2 2929 5486
A6: Acetogen Gas Chile S.A. | B6: Artículos para Seguridad | C6: Santiago | D6: Investigación en Proceso | G6: Hugo Inzulza Daneri (Gerente General) | H6: hinzulza@acetogen.cl | J6: https://cl.linkedin.com/company/acetogen | L6: Ventas: GRANDE 3 (600.000 - 1.000.000 UF) | Empleados: 57 | M6: Contactada | Q6: LinkedIn | T6: 93.333.000-1 | U6: (56) 2 2583 2780
A7: Adler Steel Chile | B7: Aceros Antiabrasivos, Barras de Aceros Especiales | C7: Santiago | D7: Aceros Especiales Minería (Procesos Críticos) | E7: Portal Minero / Licitaciones | F7: https://adler.cl/wp-content/uploads/2023/06/CatalogoAdlerJunio23.pdf | G7: Sabin Capetillo (Jefe Informática) | H7: scapetillo@adlersteel.cl | I7: https://cl.linkedin.com/in/sabin-capetillo-83376711a | J7: https://cl.linkedin.com/company/adler-steel-chile | L7: Ventas: GRANDE 3 (600.000 - 1.000.000 UF) | Empleados: 17 | M7: Contactada | Q7: LinkedIn | T7: 92.844.000-1 | U7: (56) 2 2420 5555
A8: AeroRescate Ambulancias Aéreas | B8: Transporte Aéreo, Transporte Aéreo en Helicóptero | C8: Santiago | D8: Investigación en Proceso | G8: David Acevedo Olguín (Director Corporativo) | H8: dacevedo@dap.cl | I8: https://cl.linkedin.com/in/david-acevedo-olgu%C3%ADn-01586b56 | J8: https://cl.linkedin.com/company/grupo-dap | L8: Ventas: GRANDE 4 (Mas de 1.000.000 UF) | Empleados: 35 | M8: Contactada | Q8: LinkedIn | T8: 99.543.620-5 | U8: (56) 2 3202 6890
A9: Aerocardal Ltda. | B9: Transporte Aéreo en Helicóptero, Vuelos Ambulancia | C9: Santiago | D9: Mantenimiento Digital Embraer (Servicio Autorizado) | E9: Comunicado Embraer / Newsletter | F9: https://tallyho.cl/embraer-suma-a-aerocardal-a-su-red-de-servicios-autorizados-en-chile/ | G9: Javier Arellano (Jefe IT) | H9: jarellano@aerocardal.com | I9: https://cl.linkedin.com/in/javier-arellano-28087313 | J9: https://cl.linkedin.com/company/aerocardal | L9: Ventas: GRANDE 3 (600.000 - 1.000.000 UF) | Empleados: 98 | M9: Contactada | Q9: LinkedIn | T9: 78.035.640-5 | U9: (56) 2 2377 7400
A10: Aguasin SpA | B10: Sistemas para Purificación de Agua, Tratamiento de Aguas | C10: Santiago | D10: Mantención Telemetría Plantas PW | E10: Mercado Público (ID 4076-121-LE25) | F10: https://www.portalminero.com/noticias/aguasin-y-xylem-presentan-soluciones-digitales-para-el-tratamiento-de-aguas/ | G10: Richard Correa (Gerente Admin (IT Resp)) | H10: rcorrea@aguasin.com | I10: https://cl.linkedin.com/in/richard-correa-escudero-6820b484 | J10: Aguasin | LinkedIn | L10: Ventas: GRANDE 4 (Mas de 1.000.000 UF) | Empleados: 174 | M10: Contactada | Q10: LinkedIn | T10: 76.377.649-2 | U10: (56) 2 2270 9500
A11: Agunsa, Agencias Universales S.A. | B11: Agencias de Carga, Almacenamiento de Carga, Transporte de Minerales | C11: Santiago | D11: Estrategia Global Innovación Digital | E11: LinkedIn | F11: https://cl.linkedin.com/in/carlos-ram%C3%ADrez-c%C3%A1rdenas-8b9b2b2a | G11: Carlos Ramírez (CTO Corporativo) | I11: https://cl.linkedin.com/in/carlos-ram%C3%ADrez-c%C3%A1rdenas-tecnolog%C3%ADa | J11: https://cl.linkedin.com/company/agunsa | L11: Ventas: GRANDE (Estimado por Empleados) | Empleados: 796 | M11: Contactada | Q11: LinkedIn | T11: 96.566.940-K | U11: (56) 2 2460 2700
A12: Alessandri & Cía. Ltda. | B12: Asesorías Jurídicas en Minería, Servicios Legales | C12: Santiago | D12: Implementación LegalTech & Ciberseguridad | F12: https://cl.linkedin.com/in/francisco-fern%C3%A1ndez-mancilla | G12: Francisco Javier Fernández M. (Subgerente Ops) | I12: https://cl.linkedin.com/in/francisco-fern%C3%A1ndez-mancilla | J12: https://cl.linkedin.com/company/alessandri | L12: Ventas: GRANDE 3 (600.000 - 1.000.000 UF) | Empleados: 101 | M12: Contactada | Q12: LinkedIn | T12: 79.784.430-6 | U12: (56) 2 2787 6000
A13: Alfa People Chile SpA | B13: Diseño de Sistemas ERP | C13: Santiago | D13: Proyectos Microsoft Dynamics 365 Cloud | F13: https://alfapeople.com/cl/ | G13: Carlos Amaro (CEO) | J13: https://www.linkedin.com/company/alfapeople | L13: Ventas: GRANDE 3 (600.000 - 1.000.000 UF) | Empleados: 121 | M13: Contactada | Q13: LinkedIn | T13: 76.360.577-9 | U13: (56) 2 2751 9000
A14: Aliservice | B14: Alimentación Industrial | C14: Santiago | D14: Digitalización Cadena Suministro Alimentación | F14: https://www.aliservice.cl/ | G14: Luis Alberto Santana (Gerente Adm y Finanzas) | J14: https://www.linkedin.com/company/aliservice-s-a | L14: Ventas: GRANDE 3 (600.000 - 1.000.000 UF) | Empleados: 1372 | M14: Contactada | Q14: LinkedIn | T14: 76437608-0 | U14: (56) 2 2913 5500
A15: American Parts | B15: Actividades de Apoyo para la Explotación de Minas y Canteras, Venta de Partes, Piezas y Accesorios para Vehículos Automotores | C15: Antofagasta | D15: Canal E-commerce B2B (Expansión Digital) | E15: Americanparts.cl / LinkedIn | F15: https://americanparts.cl/shop/ | G15: Patricio Herrera (Jefe de Sistemas) | H15: p.herrera@americanparts.cl | J15: https://cl.linkedin.com/company/american-parts-spa | K15: http://www.americanparts.cl | L15: Ventas: GRANDE 3 (600.000 - 1.000.000 UF) | Empleados: 38 | T15: 76.790.684-6 | U15: (56) 9 4220 1935
A16: Anakena Group | B16: Construcciones Modulares, Servicios Hoteleros | C16: Santiago | D16: Hotelería Modular Minería (Sistemas Gestión) | E16: Exponor 2024 / BCN | F16: https://www.anakenagroup.cl/2024/06/10/anakena-noticias/ | G16: Michael Salameh (Jefe de Sistemas Producción) | H16: m.salameh@anakena.cl | I16: https://cl.linkedin.com/in/michael-salameh-148509ab | J16: https://www.linkedin.com/company/anakena-chile | L16: Ventas: GRANDE 3 (600.000 - 1.000.000 UF) | Empleados: 476 | T16: 52.003.237-1 | U16: (56) 2 2951 5328
A17: Ancor Tecmin | B17: Aisladores para Anodos y Cátodos, Celdas Electrolíticas | C17: Santiago | D17: Investigación en Proceso | G17: Franco Yáñez (Jefe Automatización e Informática) | H17: f.yanez@ancortecmin.cl | I17: https://cl.linkedin.com/in/francoyanez | J17: https://cl.linkedin.com/company/ancor-tecmin | L17: Ventas: GRANDE 3 (600.000 - 1.000.000 UF) | Empleados: 191 | T17: 76.411.929-0 | U17: (56) 2 2510 6000
A18: Andes Solar | B18: Desarrollo, Construcción y Operación de Proyectos de Energía Renovable | C18: Santiago | D18: Investigación en Proceso | G18: Felipe Aguilera Moore (Jefe de Ingeniería) | H18: f.aguilera@andessolar.cl | I18: https://cl.linkedin.com/in/felipe-aguilera-moore | J18: https://www.linkedin.com/company/andessolar | L18: Ventas: GRANDE 3 (600.000 - 1.000.000 UF) | Empleados: 95 | T18: 76.271.321-7 | U18: (56) 2 2956 6230
A19: Anglo American Chile | B19: Anodos de Cobre, Cátodos de Cobre, Concentrado de Molibdeno, Sulfato de Cobre | C19: Santiago | D19: Centro Remoto IROC | E19: LinkedIn | F19: https://cl.linkedin.com/in/rodrigosubiabre | G19: Rodrigo Subiabre (VP Tech & Innov) | I19: https://cl.linkedin.com/in/rodrigo-subiabre-84130844 | J19: https://www.linkedin.com/company/anglo-american | L19: Ventas: GRANDE (Estimado por Empleados) | Empleados: 837 | T19: 77.905.330-K | U19: (56) 2 2230 6000
A20: Artilec Ltda. | B20: Cámaras IP para Vigilancia, Seguridad Industrial y Minera | C20: Santiago | D20: Investigación en Proceso | G20: Mayron Araya (Soporte Informática) | H20: maraya@artilec.cl | I20: https://cl.linkedin.com/in/mayron-araya-30a828b1 | J20: https://www.linkedin.com/company/artilec-ltda | L20: Ventas: GRANDE 3 (600.000 - 1.000.000 UF) | Empleados: 67 | T20: 79.796.310-0 | U20: (56) 2 2240 7500
A21: AtPac Doka | B21: Andamios | C21: Santiago | D21: Encofrados & Seguridad Construcción | F21: https://www.google.com/search?q=AtPac+Doka+Chile+LinkedIn | G21: Aldo Veas (Technical Manager LATAM) | I21: https://cl.linkedin.com/in/aldo-veas-2850534 | J21: https://www.linkedin.com/company/at-pac | L21: Ventas: GRANDE 2 (200.000 - 600.000 UF) | Empleados: 43 | T21: 77.383.881-K | U21: (56) 9 3394 1026
A22: Atlas Renewable Energy | B22: Plantas de Energía Solar | C22: Santiago | D22: Investigación en Proceso | G22: Francisca Latorre H. (Corporate IT Manager) | H22: flatorre@atlasrenewableenergy.com | I22: https://cl.linkedin.com/in/franciscalatorrel | J22: https://www.linkedin.com/company/atlasrenewableenergy | L22: Ventas: GRANDE 3 (600.000 - 1.000.000 UF) | Empleados: 0 | T22: 76376627-6 | U22: (56) 2 2611 8300
A23: BASF Chile S.A. | B23: Productos Químicos para la Minería | C23: Santiago | D23: Transformación Digital Clusters Región Andes | F23: https://cl.linkedin.com/in/jonathan-rojas-diaz | G23: Jonathan Rojas (Gerente Digitalización) | I23: https://cr.linkedin.com/in/jonathan-rojas-diaz | J23: https://www.linkedin.com/company/basf | L23: Ventas: GRANDE (Estimado por Empleados) | Empleados: 256 | T23: 80.043.600-1 | U23: (56) 2 2640 7000
A24: Bailac | B24: Aros y Llantas para Camiones, Reciclaje de Neumáticos OTR | C24: Santiago | D24: Tecnología Gestión Neumáticos & Economía Circular | F24: https://cl.linkedin.com/in/raimundo-bailac-pereira-b53269104 | G24: Raimundo Bailac (GG) | I24: https://cl.linkedin.com/in/raimundo-bailac-pereira-b53269104 | J24: https://cl.linkedin.com/company/bailac-thor | L24: Ventas: GRANDE 2 (200.000 - 600.000 UF) | Empleados: 95 | T24: 79.722.740-4 | U24: (56) 2 2915 9130
A25: Bailac Capacita | B25: Capacitación en Mantenimiento de Equipos Móviles, Capacitación en Seguridad Operacional, Capacitación en Soldadura (Reparación de Equipos y END) | C25: Santiago | D25: Tecnología Gestión Neumáticos & Economía Circular | F25: https://cl.linkedin.com/in/raimundo-bailac-pereira-b53269104 | G25: Raimundo Bailac (GG) | I25: https://cl.linkedin.com/in/raimundo-bailac-pereira-b53269104 | J25: https://cl.linkedin.com/in/bailac-capacita-26a872180 | L25: Ventas: PEQUEÑA 3 (10.000 - 25.000 UF) | Empleados: 5 | T25: 76.217.882-6 | U25: (56) 9 4284 6607
A26: Bailac Thor Saan Ltda. | B26: Recauchaje de Neumáticos, Servicios de Reparación de Neumáticos Gigantes a la Minería | C26: Iquique | D26: Tecnología Gestión Neumáticos & Economía Circular | F26: https://cl.linkedin.com/in/raimundo-bailac-pereira-b53269104 | G26: Raimundo Bailac (GG) | I26: https://cl.linkedin.com/in/raimundo-bailac-pereira-b53269104 | J26: https://cl.linkedin.com/company/bailacsanltda | L26: Ventas: GRANDE 3 (600.000 - 1.000.000 UF) | Empleados: 156 | T26: 78.080.330-4 | U26: (56) 57 251 8300
A27: Barraca de Fierro San Joaquín SpA | B27: Barracas de Acero, Barracas de Fierros | C27: Santiago | D27: Transformación Digital Ventas & Inventario | F27: https://cl.linkedin.com/in/martin-vera-0b1a1b1b | G27: Martín Vera (CIO/CTO) | I27: https://cl.linkedin.com/in/martin-vera-poblete-1622582a4 | J27: https://cl.linkedin.com/company/barraca-de-fierro-san-joaquin-s-a | L27: Ventas: GRANDE 2 (200.000 - 600.000 UF) | Empleados: 21 | T27: 96.654.030-3 | U27: (56) 2 2551 6867
A28: Bartech | B28: Capturadores de Información, Control de Accesos | C28: Santiago | D28: Investigación en Proceso | G28: Raul Lara (Gerente Comercial y Desarrollo) | H28: raul.lara@bartech.cl | I28: https://cl.linkedin.com/in/raul-lara-c-4626264b | J28: https://cl.linkedin.com/company/bartech-chile | L28: Ventas: GRANDE 3 (600.000 - 1.000.000 UF) | Empleados: 20 | T28: 99.539.070-1 | U28: (56) 2 2923 8600
A29: Bechtel Chile Ltda. | B29: Construcción de Plantas Mineras | C29: Santiago | D29: Sistemas IT Ingeniería Minería & Infraestructura | F29: https://cl.linkedin.com/in/felipe-espinoza-yentzen-377a3b67 | G29: Felipe Espinoza (Infrastructure Lead) | I29: https://cl.linkedin.com/in/felipe-espinoza-yentzen-377a3b67 | J29: https://www.linkedin.com/company/bechtel-corporation | L29: Ventas: GRANDE (Estimado por Empleados) | Empleados: 1820 | T29: 95.207.000-2 | U29: (56) 2 2675 1000
A30: Beiben Truck | B30: Bulldozers, Camiones Carreteros y Fuera de Carretera (OTR) | C30: Santiago | D30: Camiones Autónomos para Minería | F30: https://cl.linkedin.com/in/philipp-kaufmann-beiben-truck-94828180 | G30: Philipp Kaufmann (CEO) | I30: https://cl.linkedin.com/in/philipp-kaufmann-beiben-truck-94828180 | J30: https://www.linkedin.com/company/beiben | L30: Ventas: GRANDE 2 (200.000 - 600.000 UF) | Empleados: 13 | T30: 76.077.627-0 | U30: (56) 2 2797 6200
A31: Bertech | B31: Productos Químicos para la Mantención de Equipos Mineros, Productos Químicos para la Minería, Revestimientos Industriales | C31: Santiago | D31: Transf. Digital Revestimientos Industriales | F31: https://cl.linkedin.com/in/pedro-fernandez-parraguez | G31: Pedro Fernández Parraguez (IT Manager) | I31: https://cl.linkedin.com/in/pedro-fernandez-parraguez | J31: https://cl.linkedin.com/company/bertechgroup | L31: Ventas: GRANDE 2 (200.000 - 600.000 UF) | Empleados: 152 | T31: 76.054.686-0 | U31: (56) 2 2246 3485
A32: Biggi (Chile) S.A. | B32: Cocinas Industriales, Equipos para Preparar Alimentos | C32: Santiago | D32: IoT Equipamiento Cocinas Industriales | F32: https://www.biggi.cl/ | G32: Sergio Biggi (Gerente General) | J32: https://cl.linkedin.com/company/biggi | L32: Ventas: GRANDE 2 (200.000 - 600.000 UF) | Empleados: 6 | T32: 91.462.001-5 | U32: (56) 2 2412 6200
A33: Bimex Ltda. | B33: Equipos Eléctricos | C33: Santiago | D33: Modernización Sistemas LIS Laboratorio | F33: https://www.bimex.cl/ | G33: Alberto Harrison (General Manager) | J33: https://www.linkedin.com/company/bimex-limitada | L33: Ventas: GRANDE 2 (200.000 - 600.000 UF) | Empleados: 9 | T33: 78.836.730-9 | U33: (56) 2 2306 2200
A34: Biofiltro | B34: Plantas de Tratamiento de Aguas Servidas | C34: Santiago | D34: Automatización Tratamiento Riles (Sistema BIDA) | F34: https://cl.linkedin.com/in/ignacio-andr%C3%A9s-jofr%C3%A9-valenzuela-69902289 | G34: Ignacio Jofré Valenzuela (Subgerente Proyectos) | I34: https://cl.linkedin.com/in/ignacio-andr%C3%A9s-jofr%C3%A9-valenzuela-69902289 | J34: https://www.linkedin.com/company/biofiltro | L34: Ventas: GRANDE 2 (200.000 - 600.000 UF) | Empleados: 86 | T34: 76.337.422-K | U34: (56) 2 3224 3648
A35: Biotec Chile S.A. | B35: Detergentes | C35: Santiago | D35: Investigación en Proceso | G35: Fabián Deramond (Gerente TI y Transf. Digital) | H35: f.deramond@biotec.cl | I35: https://cl.linkedin.com/in/fabi%C3%A1n-deramond-44064918 | J35: https://cl.linkedin.com/company/biotec-chile-s-a- | L35: Ventas: GRANDE 3 (600.000 - 1.000.000 UF) | Empleados: 77 | T35: 96.025.000-1 | U35: (56) 2 2963 4500
A36: Bombas de Pozo Ltda. | B36: Proveedor Destacado, Accesorios para Perforación, Asesorías, Bombas para Pozos Profundos, Bombas Sumergibles, Bombas Sumergibles para Pozos Profundos, Cables Sumergibles, Cañerías con Hilo, Coplas y Abrazaderas, Reparación de Equipos Hidráulicos, Servicio Técnico, Tableros Eléctricos, Tuberías Flexibles para Pozos Profundos | C36: Santiago | D36: Investigación en Proceso | G36: Mauricio Illanes (Socio Técnico) | H36: m.illanes@bombasdepozo.cl | K36: http://www.bombasdepozo.cl | L36: Ventas: GRANDE 3 (600.000 - 1.000.000 UF) | Empleados: 36 | T36: 78.176.700-K | U36: (56) 2 2842 0700
A37: Bosch Rexroth Chile | B37: Bulldozers, Cargadoras Retroexcavadoras | C37: Santiago | D37: Monitoreo Predictivo | E37: Catálogo Soluciones | F37: https://www.boschrexroth.com/es/cl/noticias-e-historias/mineria/soluciones-bosch-rexroth-para-mineria/ | G37: Oscar Torres (Jefe Proyectos TI) | H37: oscar.torres@boschrexroth.cl | J37: https://cl.linkedin.com/company/bosch-rexroth-chile-spa | L37: Ventas: GRANDE 4 (Mas de 1.000.000 UF) | Empleados: 79 | T37: 76.365.959-3 | U37: (56) 2 2487 3700
A38: Bottai S.A. | B38: Prefabricados de Concreto y Hormigón, Tubos de Concreto y Hormigón | C38: Santiago | D38: Investigación en Proceso | G38: Rodrigo Gimenez Fernandez (Gerente Comercial) | H38: r.gimenez@bottai.cl | I38: https://cl.linkedin.com/in/rodrigogimenezfernandez | J38: https://cl.linkedin.com/company/bottai-s-a | L38: Ventas: GRANDE 3 (600.000 - 1.000.000 UF) | Empleados: 384 | T38: 80.125.100-5 | U38: (56) 2 2413 1200
A39: Bradken Chile | B39: Revestimientos para Molinos | C39: Santiago | D39: Investigación en Proceso | G39: Juan Carlos Rojas (IT Manager) | H39: j.rojas@bradken.com | J39: https://www.linkedin.com/company/bradkenofficial | L39: Ventas: GRANDE 3 (600.000 - 1.000.000 UF) | Empleados: 28 | T39: 76980920-1
A40: Budge Chile SpA | B40: Transmisiones Mecánicas | C40: Iquique | D40: Modernización Grid & Software Energía | F40: https://www.ge.com/news/reports/ge-chile-100-years | G40: Rodrigo Elizondo (CEO Chile) | I40: https://cl.linkedin.com/in/relizondoj | L40: Ventas: GRANDE 1 (100.000 - 200.000 UF) | Empleados: 3 | T40: 76.869.432-K | U40: (56) 2 2885 4224
...

Sheet CUENTAS_VIP_TOP
A1: Empresa | B1: Rubro | C1: Ciudad | D1: Proyecto / Oportunidad Detectada | E1: Fuente de Información | F1: Enlace a la Fuente | G1: Contacto Sniper | H1: Email de Contacto | I1: Teléfono | J1: Sitio Web | K1: RUT | L1: Contexto Empresa | M1: Categoría Venta | N1: Estado Contacto | O1: Sub-Estado | P1: Fecha Contacto | Q1: Notas CRM | R1: Medio de Contacto | S1: Próximo Seguimiento | T1: Prioridad
A2: A. Hartrodt Chile S.A. | B2: Transporte Aéreo, Transporte Marítimo, Transporte Terrestre | C2: Santiago | D2: Investigación en Proceso | G2: Hector Calderon (Jefe Informática) | H2: hcalderon@hartrodt.cl | I2: (56) 2 2483 7000 | K2: 84.007.300-9 | L2: Ventas: GRANDE 3 (600.000 - 1.000.000 UF) | Empleados: 34 | M2: Tier 1 - OPORTUNIDAD ACTIVA (VIP)
A3: A.J. Broom y Cía. S.A.C. | B3: Agencias Marítimas | C3: Santiago | D3: Plataforma Tracking Marítimo Real-Time | F3: https://www.ajbroom.cl/ | G3: Ricardo Lira (Gerente Operaciones) | I3: (56) 2 2549 8400 | K3: 91.256.000-7 | L3: Ventas: GRANDE 2 (200.000 - 600.000 UF) | Empleados: 33 | M3: Tier 1 - OPORTUNIDAD ACTIVA (VIP)
A4: AB Arriendos S.A. | B4: Arriendo de Equipos para Soldar, Compresores | C4: Santiago | D4: Expansión Arriendo Maquinaria Norte | F4: https://www.abarriendos.cl/ | G4: Roberto Carlos Bailac (Exec. Director) | I4: (56) 2 2351 5400 | K4: 96.872.010-4 | L4: Ventas: GRANDE 2 (200.000 - 600.000 UF) | Empleados: 107 | M4: Tier 1 - OPORTUNIDAD ACTIVA (VIP)
A5: ASAP Group | B5: Recuperación de Campamentos Mineros | C5: Santiago | G5: Gerente de TI / CIO (Director de Tecnología) | I5: (56) 2 2573 0471 | K5: 76.173.088-6 | L5: Ventas: GRANDE 4 (Mas de 1.000.000 UF) | Empleados: 1376 | M5: Tier 1 - VIP (Alta Venta + DM)
A6: ATS Maquinarias | B6: Plataformas Aéreas, Torres de Iluminación | C6: Santiago | G6: Gerente de TI / CIO (Director de Tecnología) | I6: (56) 9 7754 7967 | K6: 99.555.350-3 | L6: Ventas: GRANDE 3 (600.000 - 1.000.000 UF) | Empleados: 38 | M6: Tier 1 - VIP (Alta Venta + DM)
A7: Acciona Energía Chile SpA | B7: Energías Renovables | C7: Santiago | G7: Gerente de TI / CIO (Director de Tecnología) | I7: (56) 2 2751 5160 | K7: 76.492.150-K | L7: Ventas: GRANDE 4 (Mas de 1.000.000 UF) | Empleados: 182 | M7: Tier 1 - VIP (Alta Venta + DM)
A8: Acerorack | B8: Rack Altillo Estructural | C8: Santiago | G8: Gerente de TI / CIO (Director de Tecnología) | I8: (56) 9 9320 7002 | K8: 77.247.510-1 | L8: Ventas: GRANDE 3 (600.000 - 1.000.000 UF) | Empleados: 88 | M8: Tier 1 - VIP (Alta Venta + DM)
A9: Aceros Chilca | B9: Bolas de Acero Forjado para Molienda, Bolas para molienda, Revestimientos para Molinos | C9: Santiago | D9: Modernización Fundición Piezas Mineras | F9: https://www.aceroschilca.com/ | G9: Eduardo Garcia (Country Manager) | I9: (56) 2 2929 5486 | K9: 96.871.960-2 | L9: Ventas: GRANDE 2 (200.000 - 600.000 UF) | Empleados: 4 | M9: Tier 1 - OPORTUNIDAD ACTIVA (VIP)
A10: Acetogen Gas Chile S.A. | B10: Artículos para Seguridad | C10: Santiago | D10: Investigación en Proceso | G10: Hugo Inzulza Daneri (Gerente General) | H10: hinzulza@acetogen.cl | I10: (56) 2 2583 2780 | K10: 93.333.000-1 | L10: Ventas: GRANDE 3 (600.000 - 1.000.000 UF) | Empleados: 57 | M10: Tier 1 - OPORTUNIDAD ACTIVA (VIP)
A11: Adler Steel Chile | B11: Aceros Antiabrasivos, Barras de Aceros Especiales | C11: Santiago | D11: Aceros Especiales Minería (Procesos Críticos) | E11: Portal Minero / Licitaciones | F11: https://adler.cl/wp-content/uploads/2023/06/CatalogoAdlerJunio23.pdf | G11: Sabin Capetillo (Jefe Informática) | H11: scapetillo@adlersteel.cl | I11: (56) 2 2420 5555 | K11: 92.844.000-1 | L11: Ventas: GRANDE 3 (600.000 - 1.000.000 UF) | Empleados: 17 | M11: Tier 1 - OPORTUNIDAD ACTIVA (VIP)
A12: AeroRescate Ambulancias Aéreas | B12: Transporte Aéreo, Transporte Aéreo en Helicóptero | C12: Santiago | D12: Investigación en Proceso | G12: David Acevedo Olguín (Director Corporativo) | H12: dacevedo@dap.cl | I12: (56) 2 3202 6890 | K12: 99.543.620-5 | L12: Ventas: GRANDE 4 (Mas de 1.000.000 UF) | Empleados: 35 | M12: Tier 1 - OPORTUNIDAD ACTIVA (VIP)
A13: Aerocardal Ltda. | B13: Transporte Aéreo en Helicóptero, Vuelos Ambulancia | C13: Santiago | D13: Mantenimiento Digital Embraer (Servicio Autorizado) | E13: Comunicado Embraer / Newsletter | F13: https://tallyho.cl/embraer-suma-a-aerocardal-a-su-red-de-servicios-autorizados-en-chile/ | G13: Javier Arellano (Jefe IT) | H13: jarellano@aerocardal.com | I13: (56) 2 2377 7400 | K13: 78.035.640-5 | L13: Ventas: GRANDE 3 (600.000 - 1.000.000 UF) | Empleados: 98 | M13: Tier 1 - OPORTUNIDAD ACTIVA (VIP)
A14: Aguasin SpA | B14: Sistemas para Purificación de Agua, Tratamiento de Aguas | C14: Santiago | D14: Mantención Telemetría Plantas PW | E14: Mercado Público (ID 4076-121-LE25) | F14: https://www.portalminero.com/noticias/aguasin-y-xylem-presentan-soluciones-digitales-para-el-tratamiento-de-aguas/ | G14: Richard Correa (Gerente Admin (IT Resp)) | H14: rcorrea@aguasin.com | I14: (56) 2 2270 9500 | K14: 76.377.649-2 | L14: Ventas: GRANDE 4 (Mas de 1.000.000 UF) | Empleados: 174 | M14: Tier 1 - OPORTUNIDAD ACTIVA (VIP)
A15: Agunsa, Agencias Universales S.A. | B15: Agencias de Carga, Almacenamiento de Carga, Transporte de Minerales | C15: Santiago | D15: Estrategia Global Innovación Digital | E15: LinkedIn | F15: https://cl.linkedin.com/in/carlos-ram%C3%ADrez-c%C3%A1rdenas-8b9b2b2a | G15: Carlos Ramírez (CTO Corporativo) | I15: (56) 2 2460 2700 | K15: 96.566.940-K | L15: Ventas: GRANDE (Estimado por Empleados) | Empleados: 796 | M15: Tier 1 - OPORTUNIDAD ACTIVA (VIP)
A16: Aislapol S.A. | B16: Aislantes Térmicos, Envases de Plástico | C16: Santiago | G16: Gerente de TI / CIO (Director de Tecnología) | I16: (56) 2 2670 0105 | K16: 76.412.645-9 | L16: Ventas: GRANDE 4 (Mas de 1.000.000 UF) | Empleados: 358 | M16: Tier 1 - VIP (Alta Venta + DM)
A17: Alessandri & Cía. Ltda. | B17: Asesorías Jurídicas en Minería, Servicios Legales | C17: Santiago | D17: Implementación LegalTech & Ciberseguridad | F17: https://cl.linkedin.com/in/francisco-fern%C3%A1ndez-mancilla | G17: Francisco Javier Fernández M. (Subgerente Ops) | I17: (56) 2 2787 6000 | K17: 79.784.430-6 | L17: Ventas: GRANDE 3 (600.000 - 1.000.000 UF) | Empleados: 101 | M17: Tier 1 - OPORTUNIDAD ACTIVA (VIP)
A18: Alfa People Chile SpA | B18: Diseño de Sistemas ERP | C18: Santiago | D18: Proyectos Microsoft Dynamics 365 Cloud | F18: https://alfapeople.com/cl/ | G18: Carlos Amaro (CEO) | I18: (56) 2 2751 9000 | K18: 76.360.577-9 | L18: Ventas: GRANDE 3 (600.000 - 1.000.000 UF) | Empleados: 121 | M18: Tier 1 - OPORTUNIDAD ACTIVA (VIP)
A19: Aliservice | B19: Alimentación Industrial | C19: Santiago | D19: Digitalización Cadena Suministro Alimentación | F19: https://www.aliservice.cl/ | G19: Luis Alberto Santana (Gerente Adm y Finanzas) | I19: (56) 2 2913 5500 | K19: 76437608-0 | L19: Ventas: GRANDE 3 (600.000 - 1.000.000 UF) | Empleados: 1372 | M19: Tier 1 - OPORTUNIDAD ACTIVA (VIP)
A20: American Parts | B20: Actividades de Apoyo para la Explotación de Minas y Canteras, Venta de Partes, Piezas y Accesorios para Vehículos Automotores | C20: Antofagasta | D20: Canal E-commerce B2B (Expansión Digital) | E20: Americanparts.cl / LinkedIn | F20: https://americanparts.cl/shop/ | G20: Patricio Herrera (Jefe de Sistemas) | H20: p.herrera@americanparts.cl | I20: (56) 9 4220 1935 | J20: http://www.americanparts.cl | K20: 76.790.684-6 | L20: Ventas: GRANDE 3 (600.000 - 1.000.000 UF) | Empleados: 38 | M20: Tier 1 - OPORTUNIDAD ACTIVA (VIP)
A21: Anakena Group | B21: Construcciones Modulares, Servicios Hoteleros | C21: Santiago | D21: Hotelería Modular Minería (Sistemas Gestión) | E21: Exponor 2024 / BCN | F21: https://www.anakenagroup.cl/2024/06/10/anakena-noticias/ | G21: Michael Salameh (Jefe de Sistemas Producción) | H21: m.salameh@anakena.cl | I21: (56) 2 2951 5328 | K21: 52.003.237-1 | L21: Ventas: GRANDE 3 (600.000 - 1.000.000 UF) | Empleados: 476 | M21: Tier 1 - OPORTUNIDAD ACTIVA (VIP)
A22: Ancor Tecmin | B22: Aisladores para Anodos y Cátodos, Celdas Electrolíticas | C22: Santiago | D22: Investigación en Proceso | G22: Franco Yáñez (Jefe Automatización e Informática) | H22: f.yanez@ancortecmin.cl | I22: (56) 2 2510 6000 | K22: 76.411.929-0 | L22: Ventas: GRANDE 3 (600.000 - 1.000.000 UF) | Empleados: 191 | M22: Tier 1 - OPORTUNIDAD ACTIVA (VIP)
A23: Andes Solar | B23: Desarrollo, Construcción y Operación de Proyectos de Energía Renovable | C23: Santiago | D23: Investigación en Proceso | G23: Felipe Aguilera Moore (Jefe de Ingeniería) | H23: f.aguilera@andessolar.cl | I23: (56) 2 2956 6230 | K23: 76.271.321-7 | L23: Ventas: GRANDE 3 (600.000 - 1.000.000 UF) | Empleados: 95 | M23: Tier 1 - OPORTUNIDAD ACTIVA (VIP)
A24: Andinor Perforaciones Ltda. | B24: Captación de Aguas Subterráneas | C24: Santiago | G24: Gerente de TI / CIO (Director de Tecnología) | I24: (56) 2 2719 3808 | K24: 76.271.472-8 | L24: Ventas: GRANDE 3 (600.000 - 1.000.000 UF) | Empleados: 210 | M24: Tier 1 - VIP (Alta Venta + DM)
A25: Anglo American Chile | B25: Anodos de Cobre, Cátodos de Cobre, Concentrado de Molibdeno, Sulfato de Cobre | C25: Santiago | D25: Centro Remoto IROC | E25: LinkedIn | F25: https://cl.linkedin.com/in/rodrigosubiabre | G25: Rodrigo Subiabre (VP Tech & Innov) | I25: (56) 2 2230 6000 | K25: 77.905.330-K | L25: Ventas: GRANDE (Estimado por Empleados) | Empleados: 837 | M25: Tier 1 - OPORTUNIDAD ACTIVA (VIP)
A26: Anser Mining SpA | B26: Plantas Seleccionadoras Móviles | C26: Santiago | G26: Gerente de TI / CIO (Director de Tecnología) | I26: (56) 2 2435 4615 | K26: 76253942-K | L26: Ventas: GRANDE 3 (600.000 - 1.000.000 UF) | Empleados: 260 | M26: Tier 1 - VIP (Alta Venta + DM)
A27: Anval S.A. | B27: Sistemas de Pesaje Hidráulico, Sistemas para Control de Maquinarias, Sistemas para Manejo de Materiales | C27: Santiago | G27: Gerente de TI / CIO (Director de Tecnología) | I27: (56) 2 2951 6907 | K27: 76.746.640-4 | L27: Ventas: GRANDE 3 (600.000 - 1.000.000 UF) | Empleados: 24 | M27: Tier 1 - VIP (Alta Venta + DM)
A28: Análisis Ambientales S.A. | B28: Tratamiento de Aguas Servidas | C28: Santiago | G28: Gerente de TI / CIO (Director de Tecnología) | I28: (56) 2 2569 4400 | K28: 96.967.550-1 | L28: Ventas: GRANDE 3 (600.000 - 1.000.000 UF) | Empleados: 353 | M28: Tier 1 - VIP (Alta Venta + DM)
A29: Artilec Ltda. | B29: Cámaras IP para Vigilancia, Seguridad Industrial y Minera | C29: Santiago | D29: Investigación en Proceso | G29: Mayron Araya (Soporte Informática) | H29: maraya@artilec.cl | I29: (56) 2 2240 7500 | K29: 79.796.310-0 | L29: Ventas: GRANDE 3 (600.000 - 1.000.000 UF) | Empleados: 67 | M29: Tier 1 - OPORTUNIDAD ACTIVA (VIP)
A30: Asesorías Algoritmos y Mediciones Ambientales SpA | B30: Servicios de Ingeniería | C30: Santiago | G30: Gerente de TI / CIO (Director de Tecnología) | I30: (56) 2 2361 6600 | K30: 77.007.600-5 | L30: Ventas: GRANDE 3 (600.000 - 1.000.000 UF) | Empleados: 437 | M30: Tier 1 - VIP (Alta Venta + DM)
A31: AtPac Doka | B31: Andamios | C31: Santiago | D31: Encofrados & Seguridad Construcción | F31: https://www.google.com/search?q=AtPac+Doka+Chile+LinkedIn | G31: Aldo Veas (Technical Manager LATAM) | I31: (56) 9 3394 1026 | K31: 77.383.881-K | L31: Ventas: GRANDE 2 (200.000 - 600.000 UF) | Empleados: 43 | M31: Tier 1 - OPORTUNIDAD ACTIVA (VIP)
A32: Atco Sabinco | B32: Construcciones Modulares | C32: Santiago | G32: Gerente de TI / CIO (Director de Tecnología) | I32: (56) 2 2391 9800 | K32: 76.175.835-7 | L32: Ventas: GRANDE 4 (Mas de 1.000.000 UF) | Empleados: 949 | M32: Tier 1 - VIP (Alta Venta + DM)
A33: Atlas Renewable Energy | B33: Plantas de Energía Solar | C33: Santiago | D33: Investigación en Proceso | G33: Francisca Latorre H. (Corporate IT Manager) | H33: flatorre@atlasrenewableenergy.com | I33: (56) 2 2611 8300 | K33: 76376627-6 | L33: Ventas: GRANDE 3 (600.000 - 1.000.000 UF) | Empleados: 0 | M33: Tier 1 - OPORTUNIDAD ACTIVA (VIP)
A34: Attex Ltda. | B34: Spools, Tubos de Acero | C34: Santiago | G34: Gerente de TI / CIO (Director de Tecnología) | I34: (56) 2 2924 1750 | K34: 85.257.700-2 | L34: Ventas: GRANDE 3 (600.000 - 1.000.000 UF) | Empleados: 45 | M34: Tier 1 - VIP (Alta Venta + DM)
A35: Austin Powder Chile | B35: Detonantes Electrónicos, Servicios para Tronaduras | C35: Santiago | G35: Gerente de TI / CIO (Director de Tecnología) | I35: (56) 2 2374 0030 | K35: 96.511.470-K | L35: Ventas: GRANDE 3 (600.000 - 1.000.000 UF) | Empleados: 68 | M35: Tier 1 - VIP (Alta Venta + DM)
A36: Avery Dennison Chile S.A. | B36: Seguridad Industrial y Minera | C36: Santiago | G36: Gerente de TI / CIO (Director de Tecnología) | I36: (56) 2 2898 8063 | K36: 96.721.090-0 | L36: Ventas: GRANDE 4 (Mas de 1.000.000 UF) | Empleados: 62 | M36: Tier 1 - VIP (Alta Venta + DM)
A37: Axinntus Ltda. | B37: Servicios de Limpieza Industrial | C37: Antofagasta | G37: Gerente de TI / CIO (Director de Tecnología) | I37: (56) 32 220 2975 | K37: 76.189.625-3 | L37: Ventas: GRANDE 4 (Mas de 1.000.000 UF) | Empleados: 988 | M37: Tier 1 - VIP (Alta Venta + DM)
A38: B y M Agencia Marítima S.A. | B38: Agencias Marítimas | C38: Santiago | G38: Gerente de TI / CIO (Director de Tecnología) | I38: (56) 2 2347 2100 | K38: 78.986.820-4 | L38: Ventas: GRANDE 3 (600.000 - 1.000.000 UF) | Empleados: 132 | M38: Tier 1 - VIP (Alta Venta + DM)
A39: BASF Chile S.A. | B39: Productos Químicos para la Minería | C39: Santiago | D39: Transformación Digital Clusters Región Andes | F39: https://cl.linkedin.com/in/jonathan-rojas-diaz | G39: Jonathan Rojas (Gerente Digitalización) | I39: (56) 2 2640 7000 | K39: 80.043.600-1 | L39: Ventas: GRANDE (Estimado por Empleados) | Empleados: 256 | M39: Tier 1 - OPORTUNIDAD ACTIVA (VIP)
A40: BC Bearing Chile S.A. | B40: Acoplamientos Flexibles, Poleas, Rodamientos | C40: Santiago | G40: Gerente de TI / CIO (Director de Tecnología) | I40: (56) 2 2351 5332 | K40: 96.678.530-6 | L40: Ventas: GRANDE 3 (600.000 - 1.000.000 UF) | Empleados: 51 | M40: Tier 1 - VIP (Alta Venta + DM)
...

Sheet BASE_COMPLETA_LIMPIA
A1: Empresa | B1: Rubro | C1: Ciudad | D1: Email General | E1: Teléfono | F1: Contacto Sniper | G1: Email Directo / Área | H1: Sitio Web | I1: RUT | J1: Oportunidad Detectada | K1: Otros Datos | L1: Estado Contacto | M1: Sub-Estado | N1: Fecha Contacto | O1: Notas CRM | P1: Medio de Contacto | Q1: Próximo Seguimiento | R1: Prioridad | S1: Fecha_Email_Enviado
A2: 350renewables | B2: Consultoría Energías Renovables | C2: Santiago | E2: (56) 9 7648 9569 | I2: 76.429.792-K | K2: Ventas: PEQUEÑA 2 (5.000 - 10.000 UF) | Empleados: 2
A3: 3M Chile S.A. | B3: Productos Eléctricos, Productos para Seguridad | C3: Santiago | D3: atencionconsumidor@mmm.com | E3: 600 300 3636 | I3: 93.626.000-4 | K3: Ventas: MEDIANA (Estimado por Empleados) | Empleados: 179
A4: 4E Chile Giz | B4: Energía, Transmisión de Energía | C4: Santiago | D4: contacto@4echile.cl | E4: (56) 2 2306 8600 | K4: Ventas: No en base SII | Empleados: S/I
A5: A. Hartrodt Chile S.A. | B5: Transporte Aéreo, Transporte Marítimo, Transporte Terrestre | C5: Santiago | D5: ah.scl@hartrodt.com | E5: (56) 2 2483 7000 | F5: Hector Calderon (Jefe Informática) | G5: hcalderon@hartrodt.cl | I5: 84.007.300-9 | J5: Investigación en Proceso | K5: Ventas: GRANDE 3 (600.000 - 1.000.000 UF) | Empleados: 34
A6: A. Marshall Moffat Ltda. | B6: Elementos de Protección Personal, Prendas de Protección Ignífuga contra Arco Eléctrico, Ropa para Seguridad | C6: Valparaíso | D6: chile@marshallmoffat.com | E6: (56) 32 279 5401 | I6: 76.007.072-6 | K6: Ventas: GRANDE 1 (100.000 - 200.000 UF) | Empleados: 62
A7: A.J. Broom y Cía. S.A.C. | B7: Agencias Marítimas | C7: Santiago | D7: info@broomgroup.com | E7: (56) 2 2549 8400 | F7: Ricardo Lira (Gerente Operaciones) | I7: 91.256.000-7 | J7: Plataforma Tracking Marítimo Real-Time | K7: Ventas: GRANDE 2 (200.000 - 600.000 UF) | Empleados: 33
A8: A.R. Thompson Group | B8: Control y Sellado de Fluidos | C8: Concepción | D8: ventaschile@artesinc.com | E8: (56) 41 285 3903 | I8: 76.008.785-8 | K8: Ventas: PEQUEÑA 2 (5.000 - 10.000 UF) | Empleados: 7
A9: AB Arriendos S.A. | B9: Arriendo de Equipos para Soldar, Compresores | C9: Santiago | D9: abarriendos@abarriendos.cl | E9: (56) 2 2351 5400 | F9: Roberto Carlos Bailac (Exec. Director) | I9: 96.872.010-4 | J9: Expansión Arriendo Maquinaria Norte | K9: Ventas: GRANDE 2 (200.000 - 600.000 UF) | Empleados: 107
A10: Abastec, Abastecimientos Técnicos Ltda. | B10: Suministros Industriales | C10: Santiago | D10: ventas@abastec.cl | E10: (56) 2 2776 4726 | I10: 77.783.750-8 | K10: Ventas: GRANDE 1 (100.000 - 200.000 UF) | Empleados: 17
A11: Abasterm S.A. | B11: Calderas, Controles de Nivel | C11: Santiago | D11: contactoasa@abasterm.cl | E11: (56) 2 2566 6800 | I11: 99.532.330-3 | K11: Ventas: GRANDE 1 (100.000 - 200.000 UF) | Empleados: 38
A12: Abastibletec | B12: Proveedor Destacado, Proyectos y Mantenimiento Eléctrico MT y AT, Remanufactura y Metrología en Terreno, Soluciones de Energías Renovables, Soluciones de Huella de Agua y Carbono, Soluciones Eléctricas, Soluciones en Sistemas de Gestión de Energía, Soluciones en Sistemas de Gestión de Integridad de Instalaciones Eléctricas, Soluciones Térmicas, Soluciones y Servicios de Eficiencia Energética, Soluciones y Servicios de IA | C12: Santiago | D12: andre.lamagdelaine@abastibletec.cl | H12: http://www.abastible.cl/abastibletec | I12: 77.528.709-8 | K12: Ventas: MEDIANA 2 (50.000 - 100.000 UF) | Empleados: 37
A13: ABB S.A. | B13: Automatización, Energías Renovables | C13: Santiago | D13: contact.center@cl.abb.com | E13: (56) 2 2471 4100 | I13: 92.805.000-9 | K13: Ventas: GRANDE (Estimado por Empleados) | Empleados: 447
A14: ABCDust | B14: Proveedor Destacado, Control de Polvo, Enzimas para Aplicación Industrial y de Caminos, Productos Químicos, Servicios de Modelación Ambiental y Túneles de Viento, Venta de GPS y Equipamiento de Georreferenciación | C14: Santiago | D14: info@abcdust.net | E14: (56) 2 2897 4905 | H14: http://www.abcdust.net | I14: 76.343.796-5 | K14: Ventas: MEDIANA 2 (50.000 - 100.000 UF) | Empleados: 7
A15: Abengoa Chile S.A. | B15: Energía Solar | C15: Santiago | D15: comercialchile@abengoa.com | E15: (56) 2 2461 4900 | I15: 96.521.440-2 | K15: Ventas: GRANDE (Estimado por Empleados) | Empleados: 3965
A16: ABSG Consulting Inc. | B16: Servicios de Ingeniería | C16: Santiago | D16: absqechile@abs-qe.com | E16: (56) 2 2431 5334 | I16: 85.623.600-5 | K16: Ventas: PEQUEÑA 3 (10.000 - 25.000 UF) | Empleados: 9
A17: AC Perforaciones | B17: Servicios de Perforación | C17: Coquimbo | D17: contactar@acperforaciones.cl | E17: (56) 51 256 6580 | I17: 76610230-1 | K17: Ventas: GRANDE 3 (600.000 - 1.000.000 UF) | Empleados: 509
A18: Accenture Chile | B18: Asesorías Comerciales, Consultoría | C18: Santiago | D18: nestor.leal@accenture.com | E18: (56) 2 2337 7121 | I18: 78.809.770-0 | K18: Ventas: GRANDE (Estimado por Empleados) | Empleados: 2234
A19: Acciona Construcción S.A. | B19: Construcción de Obras Civiles, Construcción de Obras de Infraestructura | C19: Santiago | D19: prensa@acciona.com | E19: (56) 2 2751 5100 | I19: 59.069.860-1 | K19: Ventas: GRANDE (Estimado por Empleados) | Empleados: 3829
A20: Acciona Energía Chile SpA | B20: Energías Renovables | C20: Santiago | D20: inversores@acciona.com | E20: (56) 2 2751 5160 | F20: Gerente de TI / CIO (Director de Tecnología) | I20: 76.492.150-K | K20: Ventas: GRANDE 4 (Mas de 1.000.000 UF) | Empleados: 182
A21: Acermet Ltda. | B21: Aceros Inoxidables, Planchas de Cobre | C21: Santiago | D21: ventas.casamatriz@acermet.cl | E21: (56) 2 2584 5200 | I21: 87.717.600-2 | K21: Ventas: GRANDE 3 (600.000 - 1.000.000 UF) | Empleados: 60
A22: Acerorack | B22: Rack Altillo Estructural | C22: Santiago | D22: ventas@acerorack.cl | E22: (56) 9 9320 7002 | F22: Gerente de TI / CIO (Director de Tecnología) | I22: 77.247.510-1 | K22: Ventas: GRANDE 3 (600.000 - 1.000.000 UF) | Empleados: 88
A23: Aceros AZA | B23: Proveedor Destacado, Aceros al Carbono, Aceros Estructurales, Aceros Laminados, Angulos Laminados de Acero, Construcción de Edificios Habitacionales, Construcción de Galpones de Acero, Construcción de Obras Civiles, Construcción de Obras de Infraestructura, Construcción de Obras para Minería Subterránea | C23: Santiago | D23: contacto@aza.cl | E23: (56) 2 2677 9100 | H23: http://www.aza.cl | I23: 92.176.000-0 | K23: Ventas: GRANDE (Estimado por Empleados) | Empleados: 744
A24: Aceros Chilca | B24: Bolas de Acero Forjado para Molienda, Bolas para molienda, Revestimientos para Molinos | C24: Santiago | D24: info@aceroschilca.com | E24: (56) 2 2929 5486 | F24: Eduardo Garcia (Country Manager) | I24: 96.871.960-2 | J24: Modernización Fundición Piezas Mineras | K24: Ventas: GRANDE 2 (200.000 - 600.000 UF) | Empleados: 4
A25: Aceros Titanium Chile Ltda. | B25: Tubos de Acero | C25: Santiago | D25: ventas@acerostitanium.cl | E25: (56) 2 2948 8444 | I25: 76.190.734-4 | K25: Ventas: GRANDE 1 (100.000 - 200.000 UF) | Empleados: 9
A26: Acerostock | B26: Aceros, Aceros Inoxidables, Aluminio en Barras | C26: Santiago | D26: ventas@acerostock.cl | E26: (56) 2 2556 7677 | I26: 78.151.970-7 | K26: Ventas: PEQUEÑA 3 (10.000 - 25.000 UF) | Empleados: 3
A27: Acetogen Gas Chile S.A. | B27: Artículos para Seguridad | C27: Santiago | D27: televentas@acetogen.cl | E27: (56) 2 2583 2780 | F27: Hugo Inzulza Daneri (Gerente General) | G27: hinzulza@acetogen.cl | I27: 93.333.000-1 | J27: Investigación en Proceso | K27: Ventas: GRANDE 3 (600.000 - 1.000.000 UF) | Empleados: 57
A28: Achilles | B28: Proveedor Destacado, Auditorías Virtuales y Presenciales de la Cadena de Suministro, Cadenas de Suministro | C28: Santiago | D28: maria.peralta@achilles.com | E28: (56) 2 2585 9600 | H28: http://www.achilles.com/es/ | I28: 76.110.170-6 | K28: Ventas: MEDIANA 2 (50.000 - 100.000 UF) | Empleados: 33
A29: Acma S.A. | B29: Cadenas de Acero | C29: Santiago | D29: fduran@acma.cl | E29: (56) 2 2350 6600 | I29: 92.190.000-7 | K29: Ventas: MEDIANA (Estimado por Empleados) | Empleados: 177
A30: Acoplados Metalcar | B30: Carros de Arrastre, Transpaletas | C30: Santiago | D30: carlosd@metalcar.cl | E30: (56) 2 2238 2429 | I30: 77.611.294-1 | K30: Ventas: MEDIANA 2 (50.000 - 100.000 UF) | Empleados: 5
A31: Acquatron Comercial Ltda. | B31: Bombas Dosificadoras | C31: Santiago | D31: acquatron@tie.cl | E31: (56) 2 2264 0339 | I31: 76.682.610-5 | K31: Ventas: MEDIANA 1 (25.000 - 50.000 UF) | Empleados: 3
A32: Actilux | B32: Torres Poligonal y Tubulares | C32: Santiago | D32: info@actilux.cl | E32: (56) 2 2748 6213 | I32: 76.552.367-2 | K32: Ventas: PEQUEÑA 3 (10.000 - 25.000 UF) | Empleados: 0
A33: Acting Chile Ltda. | B33: Equipos Eléctricos, Proyectos para Iluminación | C33: Santiago | D33: contacto@acting.cl | E33: (56) 2 2736 0281 | I33: 78.177.130-9 | K33: Ventas: GRANDE 1 (100.000 - 200.000 UF) | Empleados: 23
A34: Adecco | B34: Consultora de Gestión de Recursos Humanos, Selección y Reclutamiento de Ejecutivos y Personal | C34: Santiago | D34: consultas@adecco.com | E34: (56) 2 2560 7200 | I34: 96.820.170-0 | K34: Ventas: GRANDE (Estimado por Empleados) | Empleados: 9532
A35: Adelanta Asesorías y Servicios | B35: Consultoría en Gestión de Abastecimiento | C35: Santiago | D35: adelanta@adelanta.cl | E35: (56) 9 9883 1453 | I35: 76.425.905-K | K35: Ventas: MEDIANA 2 (50.000 - 100.000 UF) | Empleados: 37
A36: Adizol | B36: Aditivos para Combustibles, Resinas para Pinturas | C36: Santiago | D36: adizol@adizol.com | E36: (56) 2 2657 2670 | I36: 76.183.070-8 | K36: Ventas: GRANDE 1 (100.000 - 200.000 UF) | Empleados: 8
A37: Adler Steel Chile | B37: Aceros Antiabrasivos, Barras de Aceros Especiales | C37: Santiago | D37: ventas@adler.cl | E37: (56) 2 2420 5555 | F37: Sabin Capetillo (Jefe Informática) | G37: scapetillo@adlersteel.cl | I37: 92.844.000-1 | J37: Aceros Especiales Minería (Procesos Críticos) | K37: Ventas: GRANDE 3 (600.000 - 1.000.000 UF) | Empleados: 17
A38: Adtrium | B38: Proveedor Destacado | C38: Santiago | D38: contacto@adtrium.cl | H38: http://www.adtrium.cl | I38: 76.261.771-4 | K38: Ventas: MEDIANA 1 (25.000 - 50.000 UF) | Empleados: 13
A39: Aenor Chile S.A. | B39: Certificación de Calidad, Servicios de Inspección Técnica | C39: Santiago | D39: masanhueza@aenor.com | E39: (56) 2 2499 9200 | I39: 96.968.660-0 | K39: Ventas: GRANDE 1 (100.000 - 200.000 UF) | Empleados: 25
A40: Aerisfogo - Aquaterra | B40: Asesoría Técnica en Indumentaria y Seguridad Industrial, Diseño y Fabricación de Ropa Técnica, Ropa de Trabajo, Comercialización de Equipos de Protección Personal (EPP), Ropa Ignífuga, Ropa Técnica para Minería, Soluciones Integrales en Vestuario Laboral, Vestuario de Alto Desempeño para Faenas, Vestuario de Seguridad Industrial | C40: Santiago | D40: aquaterra@aquaterra.cl | E40: (56) 2 2602 1020 | H40: http://www.aerisfogo.com | I40: 76.073.000-9 | K40: Ventas: MEDIANA 2 (50.000 - 100.000 UF) | Empleados: 13
...

Sheet OUTREACH_LINKEDIN
A1: Empresa | B1: Contacto | C1: Cargo | D1: Categoría | E1: LinkedIn Personal | F1: Mensaje LinkedIn — copiar y pegar | G1: Estado
A2: A. Hartrodt Chile S.A. | B2: Hector | C2: Jefe Informática | D2: Logística | E2: https://cl.linkedin.com/in/hector-calderon-gonzalez-3439a358 | F2: Hola Hector, vi que A. Hartrodt Chile S.A. opera en logística y transporte. En OpenCORE desarrollamos plataformas que conectan tracking, WMS y ERP en tiempo real. ¿Tienen desafíos con visibilidad de carga o trazabilidad operativa?
A3: A.J. Broom y Cía. S.A.C. | B3: Ricardo | C3: Gerente Operaciones | D3: Logística | E3: nan | F3: Hola Ricardo, vi que A.J. Broom y Cía. S.A.C. opera en logística y transporte. En OpenCORE desarrollamos plataformas que conectan tracking, WMS y ERP en tiempo real. ¿Tienen desafíos con visibilidad de carga o trazabilidad operativa?
A4: AB Arriendos S.A. | B4: Roberto | C4: Exec. Director | D4: Arriendo Maq. | E4: nan | F4: Hola Roberto, sé que AB Arriendos S.A. trabaja con arriendo de equipos industriales. OpenCORE desarrolla software de control de flota y mantenimiento predictivo. ¿Tienen algún desafío en la gestión de equipos o disponibilidad de activos?
A5: Aceros Chilca | B5: Eduardo | C5: Country Manager | D5: Minería | E5: nan | F5: Hola Eduardo, trabajo con empresas del sector minero en digitalización de operaciones. En OpenCORE construimos sistemas de gestión de activos y trazabilidad para faenas. ¿Están evaluando mejorar el control de procesos críticos en Aceros Chilca?
A6: Acetogen Gas Chile S.A. | B6: Hugo | C6: Gerente General | D6: Seguridad/EPP | E6: nan | F6: Hola Hugo, trabajo con distribuidores de EPP e industria química. En OpenCORE desarrollamos plataformas B2B para inventario, pedidos y trazabilidad. ¿Acetogen Gas Chile S.A. tiene desafíos en gestión de inventario o canal de ventas B2B?
A7: Adler Steel Chile | B7: Sabin | C7: Jefe Informática | D7: Minería | E7: https://cl.linkedin.com/in/sabin-capetillo-83376711a | F7: Hola Sabin, trabajo con empresas del sector minero en digitalización de operaciones. En OpenCORE construimos sistemas de gestión de activos y trazabilidad para faenas. ¿Están evaluando mejorar el control de procesos críticos en Adler Steel Chile?
A8: AeroRescate Ambulancias Aéreas | B8: David | C8: Director Corporativo | D8: Logística | E8: https://cl.linkedin.com/in/david-acevedo-olgu%C3%ADn-01586b56 | F8: Hola David, vi que AeroRescate Ambulancias Aéreas opera en logística y transporte. En OpenCORE desarrollamos plataformas que conectan tracking, WMS y ERP en tiempo real. ¿Tienen desafíos con visibilidad de carga o trazabilidad operativa?
A9: Aerocardal Ltda. | B9: Javier | C9: Jefe IT | D9: Logística | E9: https://cl.linkedin.com/in/javier-arellano-28087313 | F9: Hola Javier, vi que Aerocardal Ltda. opera en logística y transporte. En OpenCORE desarrollamos plataformas que conectan tracking, WMS y ERP en tiempo real. ¿Tienen desafíos con visibilidad de carga o trazabilidad operativa?
A10: Aguasin SpA | B10: Richard | C10: Gerente Admin (IT Resp | D10: Industrial | E10: https://cl.linkedin.com/in/richard-correa-escudero-6820b484 | F10: Hola Richard, en OpenCORE desarrollamos software para operaciones industriales: gestión de activos, trazabilidad y control operacional a medida. ¿Hay algún proceso en Aguasin SpA donde estén evaluando digitalizar o mejorar eficiencia?
A11: Agunsa, Agencias Universales S.A. | B11: Carlos | C11: CTO Corporativo | D11: Logística | E11: https://cl.linkedin.com/in/carlos-ram%C3%ADrez-c%C3%A1rdenas-tecnolog%C3%ADa | F11: Hola Carlos, vi que Agunsa, Agencias Universales S.A. opera en logística y transporte. En OpenCORE desarrollamos plataformas que conectan tracking, WMS y ERP en tiempo real. ¿Tienen desafíos con visibilidad de carga o trazabilidad operativa?
A12: Alessandri & Cía. Ltda. | B12: Francisco | C12: Subgerente Ops | D12: Minería | E12: https://cl.linkedin.com/in/francisco-fern%C3%A1ndez-mancilla | F12: Hola Francisco, trabajo con empresas del sector minero en digitalización de operaciones. En OpenCORE construimos sistemas de gestión de activos y trazabilidad para faenas. ¿Están evaluando mejorar el control de procesos críticos en Alessandri & Cía. Ltda.?
A13: Alfa People Chile SpA | B13: Carlos | C13: CEO | D13: Industrial | E13: nan | F13: Hola Carlos, en OpenCORE desarrollamos software para operaciones industriales: gestión de activos, trazabilidad y control operacional a medida. ¿Hay algún proceso en Alfa People Chile SpA donde estén evaluando digitalizar o mejorar eficiencia?
... A233: Zitrón Chile SpA | B233: Nelson | C233: Subgerente TI | D233: Industrial | E233: nan | F233: Hola Nelson, en OpenCORE desarrollamos software para operaciones industriales: gestión de activos, trazabilidad y control operacional a medida. ¿Hay algún proceso en Zitrón Chile SpA donde estén evaluando digitalizar o mejorar eficiencia?

Sheet NOTAS_DASHBOARD
A1: Fecha | B1: Comentario
A2: 17/03/2026 | B2: Probando la funcionalidad
